WARNING - Received unrecognized parameter ensemble_download_models_timeout_sec
Running on local machine
Parent Run ID: AutoML_38a04186-c68d-4f2b-ab4c-828044d54672

Current status: DatasetFeaturization. Beginning to featurize the dataset.
Current status: DatasetFeaturizationCompleted. Completed featurizing the dataset.
Heuristic parameters: Target_Lag = '[1]', Target_Rolling_Window = '3'.
WARNING - Received unrecognized parameter ensemble_download_models_timeout_sec
Traceback (most recent call last):
  File "/projappl/project_2003107/anaconda3/envs/azure_automl/lib/python3.7/site-packages/azureml/_restclient/clientbase.py", line 334, in _execute_func_internal
    return func(*args, **kwargs)
  File "/projappl/project_2003107/anaconda3/envs/azure_automl/lib/python3.7/site-packages/azureml/_restclient/operations/run_operations.py", line 515, in patch_by_exp_id
    raise models.ErrorResponseException(self._deserialize, response)
azureml._restclient.models.error_response.ErrorResponseException: Operation returned an invalid status code 'Forbidden'

The above exception was the direct cause of the following exception:

Traceback (most recent call last):
  File "/projappl/project_2003107/anaconda3/envs/azure_automl/lib/python3.7/site-packages/azureml/train/automl/_azureautomlclient.py", line 357, in fit
    parent_run_id=parent_run_id)
  File "/projappl/project_2003107/anaconda3/envs/azure_automl/lib/python3.7/site-packages/azureml/train/automl/runtime/_runtime_client.py", line 347, in _fit_local
    verifier=verifier
  File "/projappl/project_2003107/anaconda3/envs/azure_automl/lib/python3.7/site-packages/azureml/train/automl/runtime/_automl_job_phases/setup_phase.py", line 62, in run
    prep_type=prep_type)
  File "/projappl/project_2003107/anaconda3/envs/azure_automl/lib/python3.7/site-packages/azureml/train/automl/runtime/_automl_job_phases/utilities.py", line 111, in set_problem_info_for_featurized_data
    feature_sweeped_state_container=feature_sweeped_state_container)
  File "/projappl/project_2003107/anaconda3/envs/azure_automl/lib/python3.7/site-packages/azureml/train/automl/runtime/_automl_job_phases/utilities.py", line 173, in _transform_and_validate_input_data
    feature_sweeping_config=feature_sweeping_config,
  File "/projappl/project_2003107/anaconda3/envs/azure_automl/lib/python3.7/site-packages/azureml/automl/runtime/data_transformation.py", line 507, in complete_featurization
    _print_heuristics_maybe(experiment_observer, ts_transformer)
  File "/projappl/project_2003107/anaconda3/envs/azure_automl/lib/python3.7/site-packages/azureml/automl/runtime/data_transformation.py", line 744, in _print_heuristics_maybe
    cast(Any, experiment_observer).run_instance.set_tags({TimeSeries.AUTO: message})
  File "/projappl/project_2003107/anaconda3/envs/azure_automl/lib/python3.7/site-packages/azureml/core/run.py", line 1381, in set_tags
    self._client.set_tags(tags)
  File "/projappl/project_2003107/anaconda3/envs/azure_automl/lib/python3.7/site-packages/azureml/_run_impl/run_history_facade.py", line 182, in set_tags
    self.run_dto = self.run.patch_run(create_run_dto)
  File "/projappl/project_2003107/anaconda3/envs/azure_automl/lib/python3.7/site-packages/azureml/_restclient/run_client.py", line 254, in patch_run
    **kwargs)
  File "/projappl/project_2003107/anaconda3/envs/azure_automl/lib/python3.7/site-packages/azureml/_restclient/run_client.py", line 558, in _execute_with_run_expid_arguments
    copy.deepcopy(self._run_arguments_with_experiment_id), *args, **kwargs)
  File "/projappl/project_2003107/anaconda3/envs/azure_automl/lib/python3.7/site-packages/azureml/_restclient/workspace_client.py", line 86, in _execute_with_arguments
    return self._call_api(func, *args_list, **kwargs)
  File "/projappl/project_2003107/anaconda3/envs/azure_automl/lib/python3.7/site-packages/azureml/_restclient/clientbase.py", line 232, in _call_api
    return self._execute_with_base_arguments(func, *args, **kwargs)
  File "/projappl/project_2003107/anaconda3/envs/azure_automl/lib/python3.7/site-packages/azureml/_restclient/clientbase.py", line 321, in _execute_with_base_arguments
    back_off, total_retry, self._logger, func, _noop_reset, *args, **kwargs)
  File "/projappl/project_2003107/anaconda3/envs/azure_automl/lib/python3.7/site-packages/azureml/_restclient/clientbase.py", line 336, in _execute_func_internal
    left_retry = cls._handle_retry(back_off, left_retry, total_retry, error, logger, func)
  File "/projappl/project_2003107/anaconda3/envs/azure_automl/lib/python3.7/site-packages/azureml/_restclient/clientbase.py", line 377, in _handle_retry
    raise_from(UserErrorException(error_msg), error)
  File "<string>", line 3, in raise_from
azureml.exceptions._azureml_exception.UserErrorException: UserErrorException:
	Message: 
Operation returned an invalid status code 'Forbidden'. The possible reason could be:
1. You are not authorized to access this resource, or directory listing denied.
2. you may not login your azure service, or use other subscription, you can check your
default account by running azure cli commend:
'az account list -o table'.
3. You have multiple objects/login session opened, please close all session and try again.
                
	InnerException None
	ErrorResponse 
{
    "error": {
        "code": "UserError",
        "message": "\nOperation returned an invalid status code 'Forbidden'. The possible reason could be:\n1. You are not authorized to access this resource, or directory listing denied.\n2. you may not login your azure service, or use other subscription, you can check your\ndefault account by running azure cli commend:\n'az account list -o table'.\n3. You have multiple objects/login session opened, please close all session and try again.\n                "
    }
}

During handling of the above exception, another exception occurred:

Traceback (most recent call last):
  File "/projappl/project_2003107/anaconda3/envs/azure_automl/lib/python3.7/site-packages/azureml/_restclient/clientbase.py", line 334, in _execute_func_internal
    return func(*args, **kwargs)
  File "/projappl/project_2003107/anaconda3/envs/azure_automl/lib/python3.7/site-packages/azureml/_restclient/operations/events_operations.py", line 95, in post
    raise models.ErrorResponseException(self._deserialize, response)
azureml._restclient.models.error_response.ErrorResponseException: Operation returned an invalid status code 'Forbidden'

The above exception was the direct cause of the following exception:

Traceback (most recent call last):
  File "azure_automl.py", line 72, in <module>
    main(args.train_path, args.pred_path, args.n_pred, args.dt, args.target, args.time_limit_min)
  File "azure_automl.py", line 33, in main
    best_run, fitted_model = experiment.submit(automl_config, show_output=True).get_output()
  File "/projappl/project_2003107/anaconda3/envs/azure_automl/lib/python3.7/site-packages/azureml/core/experiment.py", line 211, in submit
    run = submit_func(config, self.workspace, self.name, **kwargs)
  File "/projappl/project_2003107/anaconda3/envs/azure_automl/lib/python3.7/site-packages/azureml/train/automl/automlconfig.py", line 100, in _automl_static_submit
    show_output)
  File "/projappl/project_2003107/anaconda3/envs/azure_automl/lib/python3.7/site-packages/azureml/train/automl/automlconfig.py", line 258, in _start_execution
    automl_run = _default_execution(experiment, settings_obj, fit_params, True, show_output, parent_run_id)
  File "/projappl/project_2003107/anaconda3/envs/azure_automl/lib/python3.7/site-packages/azureml/train/automl/automlconfig.py", line 124, in _default_execution
    return automl_estimator.fit(**fit_params)
  File "/projappl/project_2003107/anaconda3/envs/azure_automl/lib/python3.7/site-packages/azureml/train/automl/_azureautomlclient.py", line 366, in fit
    self._fail_parent_run(error_details=e)
  File "/projappl/project_2003107/anaconda3/envs/azure_automl/lib/python3.7/site-packages/azureml/train/automl/_azureautomlclient.py", line 753, in _fail_parent_run
    self.current_run._fail_with_error(error_details)
  File "/projappl/project_2003107/anaconda3/envs/azure_automl/lib/python3.7/site-packages/azureml/train/automl/run.py", line 1252, in _fail_with_error
    error_code=common_utilities.get_error_code(interpreted_exception))
  File "/projappl/project_2003107/anaconda3/envs/azure_automl/lib/python3.7/site-packages/azureml/core/run.py", line 1226, in fail
    self._client.fail(error_details=error_details, error_code=error_code, _set_status=_set_status)
  File "/projappl/project_2003107/anaconda3/envs/azure_automl/lib/python3.7/site-packages/azureml/_run_impl/run_history_facade.py", line 586, in fail
    self.run.post_event_error(error_dict, caller=self.identity)
  File "/projappl/project_2003107/anaconda3/envs/azure_automl/lib/python3.7/site-packages/azureml/_restclient/run_client.py", line 484, in post_event_error
    return self.post_event(event, is_async=is_async, caller=caller, custom_headers=custom_headers)
  File "/projappl/project_2003107/anaconda3/envs/azure_automl/lib/python3.7/site-packages/azureml/_restclient/run_client.py", line 305, in post_event
    return self._execute_with_run_arguments(self._client.events.post, **kwargs)
  File "/projappl/project_2003107/anaconda3/envs/azure_automl/lib/python3.7/site-packages/azureml/_restclient/run_client.py", line 553, in _execute_with_run_arguments
    return self._execute_with_arguments(func, copy.deepcopy(self._run_arguments), *args, **kwargs)
  File "/projappl/project_2003107/anaconda3/envs/azure_automl/lib/python3.7/site-packages/azureml/_restclient/workspace_client.py", line 86, in _execute_with_arguments
    return self._call_api(func, *args_list, **kwargs)
  File "/projappl/project_2003107/anaconda3/envs/azure_automl/lib/python3.7/site-packages/azureml/_restclient/clientbase.py", line 232, in _call_api
    return self._execute_with_base_arguments(func, *args, **kwargs)
  File "/projappl/project_2003107/anaconda3/envs/azure_automl/lib/python3.7/site-packages/azureml/_restclient/clientbase.py", line 321, in _execute_with_base_arguments
    back_off, total_retry, self._logger, func, _noop_reset, *args, **kwargs)
  File "/projappl/project_2003107/anaconda3/envs/azure_automl/lib/python3.7/site-packages/azureml/_restclient/clientbase.py", line 336, in _execute_func_internal
    left_retry = cls._handle_retry(back_off, left_retry, total_retry, error, logger, func)
  File "/projappl/project_2003107/anaconda3/envs/azure_automl/lib/python3.7/site-packages/azureml/_restclient/clientbase.py", line 377, in _handle_retry
    raise_from(UserErrorException(error_msg), error)
  File "<string>", line 3, in raise_from
azureml.exceptions._azureml_exception.UserErrorException: UserErrorException:
	Message: 
Operation returned an invalid status code 'Forbidden'. The possible reason could be:
1. You are not authorized to access this resource, or directory listing denied.
2. you may not login your azure service, or use other subscription, you can check your
default account by running azure cli commend:
'az account list -o table'.
3. You have multiple objects/login session opened, please close all session and try again.
                
	InnerException None
	ErrorResponse 
{
    "error": {
        "code": "UserError",
        "message": "\nOperation returned an invalid status code 'Forbidden'. The possible reason could be:\n1. You are not authorized to access this resource, or directory listing denied.\n2. you may not login your azure service, or use other subscription, you can check your\ndefault account by running azure cli commend:\n'az account list -o table'.\n3. You have multiple objects/login session opened, please close all session and try again.\n                "
    }
}
